Workbook

Sheet Data
A1: کد شعبه | B1: نام شعبه | C1: منطقه | D1: میانگین سپرده ها | E1: تعداد سپرده ها | F1: میانگین تسهیلات | G1: تعداد تسهیلات | H1: میانگین تعهدات | I1: تعداد تعهدات | J1: حجم عملیات | K1: سود (زیان)
A2: 101 | B2: غدير | C2: تهران غرب | D2: =AVERAGEIF('سپرده ها'!A:A, A2, 'سپرده ها'!Q:Q) -> 4.3914706e+13 | E2: =AVERAGEIF('تعداد سپرده ها'!A:A, A2, 'تعداد سپرده ها'!C:C) -> 33733.417 | F2: =AVERAGEIF('میانگین مانده تسهیلات'!A:A, A2, 'میانگین مانده تسهیلات'!C:C) -> 8.4358392e+13 | G2: =AVERAGEIF('میانگین تعداد تسهیلات'!A:A, A2, 'میانگین تعداد تسهیلات'!C:C) -> 609.75 | H2: =AVERAGEIF('میانگین تعهدات'!A:A, A2, 'میانگین تعهدات'!C:C) -> 9.1078514e+13 | I2: =AVERAGEIF('میانگین تعداد تعهدات'!A:A, A2, 'میانگین تعداد تعهدات'!C:C) -> 401 | J2: {=LOOKUP(2, 1/('تعداد حجم عملیات'!A:A=A2), 'تعداد حجم عملیات'!C:C)} -> 181485 | K2: {=LOOKUP(2, 1/('سود و زیان'!B:B=A2), 'سود و زیان'!C:C)} -> 10765429399129
A3: 102 | B3: آفريقا | C3: تهران مرکز | D3: =AVERAGEIF('سپرده ها'!A:A, A3, 'سپرده ها'!Q:Q) -> 5.4692261e+13 | E3: =AVERAGEIF('تعداد سپرده ها'!A:A, A3, 'تعداد سپرده ها'!C:C) -> 69538.917 | F3: =AVERAGEIF('میانگین مانده تسهیلات'!A:A, A3, 'میانگین مانده تسهیلات'!C:C) -> 1.3314265e+14 | G3: =AVERAGEIF('میانگین تعداد تسهیلات'!A:A, A3, 'میانگین تعداد تسهیلات'!C:C) -> 1028.9167 | H3: =AVERAGEIF('میانگین تعهدات'!A:A, A3, 'میانگین تعهدات'!C:C) -> 1.4667279e+14 | I3: =AVERAGEIF('میانگین تعداد تعهدات'!A:A, A3, 'میانگین تعداد تعهدات'!C:C) -> 600.58333 | J3: {=LOOKUP(2, 1/('تعداد حجم عملیات'!A:A=A3), 'تعداد حجم عملیات'!C:C)} -> 257150 | K3: {=LOOKUP(2, 1/('سود و زیان'!B:B=A3), 'سود و زیان'!C:C)} -> 14016278358235
A4: 103 | B4: فاطمي | C4: تهران مرکز | D4: =AVERAGEIF('سپرده ها'!A:A, A4, 'سپرده ها'!Q:Q) -> 1.5115661e+13 | E4: =AVERAGEIF('تعداد سپرده ها'!A:A, A4, 'تعداد سپرده ها'!C:C) -> 27736.667 | F4: =AVERAGEIF('میانگین مانده تسهیلات'!A:A, A4, 'میانگین مانده تسهیلات'!C:C) -> 2.356769e+13 | G4: =AVERAGEIF('میانگین تعداد تسهیلات'!A:A, A4, 'میانگین تعداد تسهیلات'!C:C) -> 255.25 | H4: =AVERAGEIF('میانگین تعهدات'!A:A, A4, 'میانگین تعهدات'!C:C) -> 2.10695e+13 | I4: =AVERAGEIF('میانگین تعداد تعهدات'!A:A, A4, 'میانگین تعداد تعهدات'!C:C) -> 251 | J4: {=LOOKUP(2, 1/('تعداد حجم عملیات'!A:A=A4), 'تعداد حجم عملیات'!C:C)} -> 127420 | K4: {=LOOKUP(2, 1/('سود و زیان'!B:B=A4), 'سود و زیان'!C:C)} -> -5689428057655
A5: 104 | B5: کارگرشمالي | C5: تهران غرب | D5: =AVERAGEIF('سپرده ها'!A:A, A5, 'سپرده ها'!Q:Q) -> 1.4389436e+13 | E5: =AVERAGEIF('تعداد سپرده ها'!A:A, A5, 'تعداد سپرده ها'!C:C) -> 30743.167 | F5: =AVERAGEIF('میانگین مانده تسهیلات'!A:A, A5, 'میانگین مانده تسهیلات'!C:C) -> 1.0118969e+13 | G5: =AVERAGEIF('میانگین تعداد تسهیلات'!A:A, A5, 'میانگین تعداد تسهیلات'!C:C) -> 201.16667 | H5: =AVERAGEIF('میانگین تعهدات'!A:A, A5, 'میانگین تعهدات'!C:C) -> 4.085219e+12 | I5: =AVERAGEIF('میانگین تعداد تعهدات'!A:A, A5, 'میانگین تعداد تعهدات'!C:C) -> 168 | J5: {=LOOKUP(2, 1/('تعداد حجم عملیات'!A:A=A5), 'تعداد حجم عملیات'!C:C)} -> 129994 | K5: {=LOOKUP(2, 1/('سود و زیان'!B:B=A5), 'سود و زیان'!C:C)} -> 1452637742913
A6: 105 | B6: پاسداران | C6: تهران شرق | D6: =AVERAGEIF('سپرده ها'!A:A, A6, 'سپرده ها'!Q:Q) -> 2.8650134e+13 | E6: =AVERAGEIF('تعداد سپرده ها'!A:A, A6, 'تعداد سپرده ها'!C:C) -> 32499.833 | F6: =AVERAGEIF('میانگین مانده تسهیلات'!A:A, A6, 'میانگین مانده تسهیلات'!C:C) -> 51372721432195 | G6: =AVERAGEIF('میانگین تعداد تسهیلات'!A:A, A6, 'میانگین تعداد تسهیلات'!C:C) -> 251.75 | H6: =AVERAGEIF('میانگین تعهدات'!A:A, A6, 'میانگین تعهدات'!C:C) -> 4.3408683e+13 | I6: =AVERAGEIF('میانگین تعداد تعهدات'!A:A, A6, 'میانگین تعداد تعهدات'!C:C) -> 159.75 | J6: {=LOOKUP(2, 1/('تعداد حجم عملیات'!A:A=A6), 'تعداد حجم عملیات'!C:C)} -> 99099 | K6: {=LOOKUP(2, 1/('سود و زیان'!B:B=A6), 'سود و زیان'!C:C)} -> 3962061437580
A7: 106 | B7: حافظ | C7: تهران مرکز | D7: =AVERAGEIF('سپرده ها'!A:A, A7, 'سپرده ها'!Q:Q) -> 1.384646e+13 | E7: =AVERAGEIF('تعداد سپرده ها'!A:A, A7, 'تعداد سپرده ها'!C:C) -> 25155.583 | F7: =AVERAGEIF('میانگین مانده تسهیلات'!A:A, A7, 'میانگین مانده تسهیلات'!C:C) -> 2.6710228e+13 | G7: =AVERAGEIF('میانگین تعداد تسهیلات'!A:A, A7, 'میانگین تعداد تسهیلات'!C:C) -> 362.16667 | H7: =AVERAGEIF('میانگین تعهدات'!A:A, A7, 'میانگین تعهدات'!C:C) -> 4.4842936e+11 | I7: =AVERAGEIF('میانگین تعداد تعهدات'!A:A, A7, 'میانگین تعداد تعهدات'!C:C) -> 24.25 | J7: {=LOOKUP(2, 1/('تعداد حجم عملیات'!A:A=A7), 'تعداد حجم عملیات'!C:C)} -> 144687 | K7: {=LOOKUP(2, 1/('سود و زیان'!B:B=A7), 'سود و زیان'!C:C)} -> 1447626472292
A8: 107 | B8: تهرانپارس | C8: تهران شرق | D8: =AVERAGEIF('سپرده ها'!A:A, A8, 'سپرده ها'!Q:Q) -> 1.1899344e+13 | E8: =AVERAGEIF('تعداد سپرده ها'!A:A, A8, 'تعداد سپرده ها'!C:C) -> 47342.667 | F8: =AVERAGEIF('میانگین مانده تسهیلات'!A:A, A8, 'میانگین مانده تسهیلات'!C:C) -> 3.7427406e+12 | G8: =AVERAGEIF('میانگین تعداد تسهیلات'!A:A, A8, 'میانگین تعداد تسهیلات'!C:C) -> 369.25 | H8: =AVERAGEIF('میانگین تعهدات'!A:A, A8, 'میانگین تعهدات'!C:C) -> 4.62786e+10 | I8: =AVERAGEIF('میانگین تعداد تعهدات'!A:A, A8, 'میانگین تعداد تعهدات'!C:C) -> 12.583333 | J8: {=LOOKUP(2, 1/('تعداد حجم عملیات'!A:A=A8), 'تعداد حجم عملیات'!C:C)} -> 164084 | K8: {=LOOKUP(2, 1/('سود و زیان'!B:B=A8), 'سود و زیان'!C:C)} -> 1774546466530
A9: 108 | B9: نياوران | C9: تهران شرق | D9: =AVERAGEIF('سپرده ها'!A:A, A9, 'سپرده ها'!Q:Q) -> 1.9377069e+13 | E9: =AVERAGEIF('تعداد سپرده ها'!A:A, A9, 'تعداد سپرده ها'!C:C) -> 27552.167 | F9: =AVERAGEIF('میانگین مانده تسهیلات'!A:A, A9, 'میانگین مانده تسهیلات'!C:C) -> 10681752675233 | G9: =AVERAGEIF('میانگین تعداد تسهیلات'!A:A, A9, 'میانگین تعداد تسهیلات'!C:C) -> 226.08333 | H9: =AVERAGEIF('میانگین تعهدات'!A:A, A9, 'میانگین تعهدات'!C:C) -> 1.0910486e+13 | I9: =AVERAGEIF('میانگین تعداد تعهدات'!A:A, A9, 'میانگین تعداد تعهدات'!C:C) -> 92.833333 | J9: {=LOOKUP(2, 1/('تعداد حجم عملیات'!A:A=A9), 'تعداد حجم عملیات'!C:C)} -> 137950 | K9: {=LOOKUP(2, 1/('سود و زیان'!B:B=A9), 'سود و زیان'!C:C)} -> 902181992219
A10: 109 | B10: بازار | C10: تهران مرکز | D10: =AVERAGEIF('سپرده ها'!A:A, A10, 'سپرده ها'!Q:Q) -> 7.2867726e+12 | E10: =AVERAGEIF('تعداد سپرده ها'!A:A, A10, 'تعداد سپرده ها'!C:C) -> 19854.083 | F10: =AVERAGEIF('میانگین مانده تسهیلات'!A:A, A10, 'میانگین مانده تسهیلات'!C:C) -> 7.0493204e+12 | G10: =AVERAGEIF('میانگین تعداد تسهیلات'!A:A, A10, 'میانگین تعداد تسهیلات'!C:C) -> 192.25 | H10: =AVERAGEIF('میانگین تعهدات'!A:A, A10, 'میانگین تعهدات'!C:C) -> 6.1473826e+11 | I10: =AVERAGEIF('میانگین تعداد تعهدات'!A:A, A10, 'میانگین تعداد تعهدات'!C:C) -> 7.75 | J10: {=LOOKUP(2, 1/('تعداد حجم عملیات'!A:A=A10), 'تعداد حجم عملیات'!C:C)} -> 128843 | K10: {=LOOKUP(2, 1/('سود و زیان'!B:B=A10), 'سود و زیان'!C:C)} -> 1187645074535
A11: 110 | B11: قائم مقام | C11: تهران مرکز | D11: =AVERAGEIF('سپرده ها'!A:A, A11, 'سپرده ها'!Q:Q) -> 2.607854e+13 | E11: =AVERAGEIF('تعداد سپرده ها'!A:A, A11, 'تعداد سپرده ها'!C:C) -> 19755 | F11: =AVERAGEIF('میانگین مانده تسهیلات'!A:A, A11, 'میانگین مانده تسهیلات'!C:C) -> 1.9697632e+13 | G11: =AVERAGEIF('میانگین تعداد تسهیلات'!A:A, A11, 'میانگین تعداد تسهیلات'!C:C) -> 304.91667 | H11: =AVERAGEIF('میانگین تعهدات'!A:A, A11, 'میانگین تعهدات'!C:C) -> 140101370888807 | I11: =AVERAGEIF('میانگین تعداد تعهدات'!A:A, A11, 'میانگین تعداد تعهدات'!C:C) -> 848 | J11: {=LOOKUP(2, 1/('تعداد حجم عملیات'!A:A=A11), 'تعداد حجم عملیات'!C:C)} -> 157288 | K11: {=LOOKUP(2, 1/('سود و زیان'!B:B=A11), 'سود و زیان'!C:C)} -> 5635848070304
A12: 111 | B12: سعادت آباد | C12: تهران غرب | D12: =AVERAGEIF('سپرده ها'!A:A, A12, 'سپرده ها'!Q:Q) -> 3.3570044e+13 | E12: =AVERAGEIF('تعداد سپرده ها'!A:A, A12, 'تعداد سپرده ها'!C:C) -> 68620 | F12: =AVERAGEIF('میانگین مانده تسهیلات'!A:A, A12, 'میانگین مانده تسهیلات'!C:C) -> 3.1354803e+13 | G12: =AVERAGEIF('میانگین تعداد تسهیلات'!A:A, A12, 'میانگین تعداد تسهیلات'!C:C) -> 277.58333 | H12: =AVERAGEIF('میانگین تعهدات'!A:A, A12, 'میانگین تعهدات'!C:C) -> 1.5679185e+13 | I12: =AVERAGEIF('میانگین تعداد تعهدات'!A:A, A12, 'میانگین تعداد تعهدات'!C:C) -> 238.66667 | J12: {=LOOKUP(2, 1/('تعداد حجم عملیات'!A:A=A12), 'تعداد حجم عملیات'!C:C)} -> 220495 | K12: {=LOOKUP(2, 1/('سود و زیان'!B:B=A12), 'سود و زیان'!C:C)} -> 3620277750769
A13: 112 | B13: تجريش | C13: تهران مرکز | D13: =AVERAGEIF('سپرده ها'!A:A, A13, 'سپرده ها'!Q:Q) -> 1.9356835e+13 | E13: =AVERAGEIF('تعداد سپرده ها'!A:A, A13, 'تعداد سپرده ها'!C:C) -> 30793.833 | F13: =AVERAGEIF('میانگین مانده تسهیلات'!A:A, A13, 'میانگین مانده تسهیلات'!C:C) -> 2.3370004e+13 | G13: =AVERAGEIF('میانگین تعداد تسهیلات'!A:A, A13, 'میانگین تعداد تسهیلات'!C:C) -> 481.41667 | H13: =AVERAGEIF('میانگین تعهدات'!A:A, A13, 'میانگین تعهدات'!C:C) -> 4.5895014e+13 | I13: =AVERAGEIF('میانگین تعداد تعهدات'!A:A, A13, 'میانگین تعداد تعهدات'!C:C) -> 99.833333 | J13: {=LOOKUP(2, 1/('تعداد حجم عملیات'!A:A=A13), 'تعداد حجم عملیات'!C:C)} -> 146268 | K13: {=LOOKUP(2, 1/('سود و زیان'!B:B=A13), 'سود و زیان'!C:C)} -> 1838148431757
... A224: 4021 | B224: بازار سما عسلويه | C224: جنوب غرب | D224: =AVERAGEIF('سپرده ها'!A:A, A224, 'سپرده ها'!Q:Q) -> 2.6559963e+12 | E224: =AVERAGEIF('تعداد سپرده ها'!A:A, A224, 'تعداد سپرده ها'!C:C) -> 39384.583 | F224: =AVERAGEIF('میانگین مانده تسهیلات'!A:A, A224, 'میانگین مانده تسهیلات'!C:C) -> 2.7645252e+11 | G224: =AVERAGEIF('میانگین تعداد تسهیلات'!A:A, A224, 'میانگین تعداد تسهیلات'!C:C) -> 116.08333 | H224: =AVERAGEIF('میانگین تعهدات'!A:A, A224, 'میانگین تعهدات'!C:C) -> 7.0301845e+11 | I224: =AVERAGEIF('میانگین تعداد تعهدات'!A:A, A224, 'میانگین تعداد تعهدات'!C:C) -> 18.25 | J224: {=LOOKUP(2, 1/('تعداد حجم عملیات'!A:A=A224), 'تعداد حجم عملیات'!C:C)} -> 57622 | K224: {=LOOKUP(2, 1/('سود و زیان'!B:B=A224), 'سود و زیان'!C:C)} -> 226579527465

Sheet سپرده ها
A1: ID_Branch | B1: SHYEARMONTH | C1: avg_jari | D1: avg_pasandaz | E1: avg_moddatdar | F1: avg | G1: avg_jari_mozoon | H1: avg_pasandaz_mozoon | I1: avg_moddatdar_mozoon | J1: avg_mozoon | K1: tedad_moshtarian_balaye20darsad | L1: mojmooe_risk_tamarkoz | M1: avg_mozoon_tadilshode | N1: avg_pishdaryaft | O1: avg_sepordenaghdi | P1: avg_sayeresepordeha | Q1: avg_Total
A2: 101 | B2: 140401 | C2: 2.4673808e+12 | D2: 5.3032648e+11 | E2: 1.2925216e+13 | F2: 1.5922923e+13 | G2: 2.8178007e+12 | H2: 6.0564397e+11 | I2: 1.3410803e+13 | J2: 1.6834248e+13 | M2: 1.6834248e+13 | N2: 3.7549923e+11 | O2: 1.1950741e+12 | P2: 1.8886671e+13 | Q2: 3.7291492e+13
A3: 102 | B3: 140401 | C3: 4.1438481e+12 | D3: 1.2779024e+12 | E3: 16594497948378 | F3: 22016248459028 | G3: 4.7323615e+12 | H3: 1.4593914e+12 | I3: 1.6220076e+13 | J3: 2.2411829e+13 | M3: 2.2411829e+13 | N3: 5025759596145 | O3: 4.4141644e+12 | P3: 1.3941577e+13 | Q3: 4.579333e+13
A4: 103 | B4: 140401 | C4: 8.2298506e+11 | D4: 2.4432673e+11 | E4: 7.4127162e+12 | F4: 8.480028e+12 | G4: 9.3986623e+11 | H4: 2.7902625e+11 | I4: 7.0513018e+12 | J4: 8.2701943e+12 | M4: 8.2701943e+12 | N4: 945719998 | O4: 5.5564997e+11 | P4: 4.0291026e+12 | Q4: 1.2855893e+13
A5: 104 | B5: 140401 | C5: 5.7113381e+11 | D5: 2.412535e+11 | E5: 1.0701032e+13 | F5: 1.1513419e+13 | G5: 6.5224681e+11 | H5: 2.7551656e+11 | I5: 1.0290433e+13 | J5: 1.1218196e+13 | M5: 1.1218196e+13 | N5: 0 | O5: 1.7032026e+11 | P5: 2.325096e+12 | Q5: 1.3713613e+13
A6: 105 | B6: 140401 | C6: 1.4449018e+11 | D6: 1.9606388e+11 | E6: 1.3950256e+13 | F6: 1.429081e+13 | G6: 1.6501082e+11 | H6: 2.2390906e+11 | I6: 1.3284298e+13 | J6: 13673218196141 | M6: 13673218196141 | N6: 11160547440 | O6: 6.3249875e+11 | P6: 1.2574336e+13 | Q6: 2.6891213e+13
A7: 106 | B7: 140401 | C7: 8.3519677e+11 | D7: 1.4301162e+11 | E7: 7.807853e+12 | F7: 8.7860614e+12 | G7: 9.5381225e+11 | H7: 1.6332227e+11 | I7: 6.8838405e+12 | J7: 8.000975e+12 | K7: 1 | L7: 0.310951 | M7: 7.0244872e+12 | N7: 0 | O7: 2.3846314e+10 | P7: 6.8808309e+12 | Q7: 1.3929164e+13
A8: 107 | B8: 140401 | C8: 1.5704427e+11 | D8: 3.3216288e+11 | E8: 9.8222063e+12 | F8: 1.0311413e+13 | G8: 1.7934785e+11 | H8: 3.7933698e+11 | I8: 9.3058431e+12 | J8: 9.8645279e+12 | M8: 9.8645279e+12 | N8: 0 | O8: 5.6418941e+08 | P8: 1.1974642e+12 | Q8: 1.1062556e+13
A9: 108 | B9: 140401 | C9: 3.2931118e+11 | D9: 2.4114143e+11 | E9: 1.5097247e+13 | F9: 1.56677e+13 | G9: 3.7608029e+11 | H9: 2.7538857e+11 | I9: 1.410415e+13 | J9: 1.4755619e+13 | M9: 1.4755619e+13 | N9: 0 | O9: 2.2802369e+11 | P9: 3.0333111e+12 | Q9: 1.8016954e+13
A10: 109 | B10: 140401 | C10: 1.0138882e+12 | D10: 1.9554292e+11 | E10: 4.6152044e+12 | F10: 5.8246355e+12 | G10: 1.1578816e+12 | H10: 2.2331412e+11 | I10: 4.4685932e+12 | J10: 5.8497889e+12 | M10: 5.8497889e+12 | N10: 2.155427e+10 | O10: 398125000 | P10: 7.9476016e+11 | Q10: 6.6665014e+12
A11: 110 | B11: 140401 | C11: 1.7353873e+12 | D11: 1.7001045e+11 | E11: 1.1837251e+13 | F11: 1.3742649e+13 | G11: 1.9818487e+12 | H11: 1.9415551e+11 | I11: 1.1174933e+13 | J11: 1.3350938e+13 | M11: 1.3350938e+13 | N11: 154372010061 | O11: 3563790450827 | P11: 4.24125e+12 | Q11: 2.131035e+13
A12: 111 | B12: 140401 | C12: 1.3031296e+13 | D12: 7.9906479e+11 | E12: 1.8819879e+13 | F12: 3.2650239e+13 | G12: 1.4882014e+13 | H12: 9.1254878e+11 | I12: 1.5451723e+13 | J12: 3.1246285e+13 | K12: 1 | L12: 0.38241 | M12: 2.4976687e+13 | N12: 3.4364613e+10 | O12: 6.8839403e+11 | P12: 2.6152794e+12 | Q12: 2.8314725e+13
A13: 112 | B13: 140401 | C13: 1.2222365e+12 | D13: 3.5204269e+11 | E13: 1.2842662e+13 | F13: 1.4416941e+13 | G13: 1.3958198e+12 | H13: 4.0204015e+11 | I13: 1.2206911e+13 | J13: 1.4004771e+13 | M13: 1.4004771e+13 | N13: 9.8061867e+09 | O13: 2.4178135e+10 | P13: 3.6218263e+12 | Q13: 1.7660582e+13
A14: 114 | B14: 140401 | C14: 1.2835346e+12 | D14: 5.771729e+11 | E14: 1.4164659e+13 | F14: 1.6025366e+13 | G14: 1.4658235e+12 | H14: 6.5914357e+11 | I14: 1.3589007e+13 | J14: 15713974274049 | M14: 15713974274049 | N14: 0 | O14: 849224856517 | P14: 2.9624558e+12 | Q14: 1.9525655e+13
A15: 115 | B15: 140401 | C15: 1.1049918e+12 | D15: 6.8344825e+11 | E15: 1.9803123e+13 | F15: 2.1591563e+13 | G15: 1.2619238e+12 | H15: 7.8051225e+11 | I15: 1.8733318e+13 | J15: 2.0775754e+13 | M15: 2.0775754e+13 | N15: 5368387830 | O15: 8.0466735e+10 | P15: 1.0426063e+12 | Q15: 21904195916897
A16: 116 | B16: 140401 | C16: 3.1549826e+11 | D16: 4.7382585e+11 | E16: 1.6043496e+13 | F16: 1.683282e+13 | G16: 3.6030564e+11 | H16: 5.4111907e+11 | I16: 1.480497e+13 | J16: 1.5706395e+13 | M16: 1.5706395e+13 | N16: 0 | O16: 1.4091404e+11 | P16: 3.899177e+12 | Q16: 1.9746486e+13
A17: 117 | B17: 140401 | C17: 1.8171771e+12 | D17: 1.2560406e+12 | E17: 2.7992471e+13 | F17: 3.1065689e+13 | G17: 2.0752544e+12 | H17: 1.4344248e+12 | I17: 2.6171365e+13 | J17: 2.9681044e+13 | M17: 2.9681044e+13 | N17: 0 | O17: 1.8479126e+12 | P17: 7.3518771e+12 | Q17: 3.8880834e+13
A18: 118 | B18: 140401 | C18: 3.7123912e+11 | D18: 1.1252565e+11 | E18: 4.6725437e+12 | F18: 5.1563084e+12 | G18: 4.2396287e+11 | H18: 1.2850666e+11 | I18: 4.5003791e+12 | J18: 5.0528486e+12 | M18: 5.0528486e+12 | N18: 1.101127e+11 | O18: 9001655066 | P18: 1.3412898e+12 | Q18: 6.5132528e+12
A19: 119 | B19: 140401 | C19: 6.8909803e+11 | D19: 5.1878892e+11 | E19: 6.1197407e+12 | F19: 7.3276276e+12 | G19: 7.8696442e+11 | H19: 5.9246784e+11 | I19: 6.027045e+12 | J19: 7.4064772e+12 | M19: 7.4064772e+12 | N19: 1.3471564e+09 | O19: 2.0091213e+10 | P19: 5.0356139e+12 | Q19: 1.246353e+13
A20: 120 | B20: 140401 | C20: 2.6022353e+11 | D20: 9.7854727e+10 | E20: 1.1864625e+12 | F20: 1.5445407e+12 | G20: 2.9718074e+11 | H20: 1.1175215e+11 | I20: 1.2952124e+12 | J20: 1.7041453e+12 | M20: 1.7041453e+12 | N20: 103099593 | O20: 2.7580394e+10 | P20: 1990056078 | Q20: 1.7338189e+12
A21: 121 | B21: 140401 | C21: 2.8164504e+11 | D21: 1.4617502e+11 | E21: 3.6333058e+12 | F21: 4.0611258e+12 | G21: 3.2164454e+11 | H21: 1.6693494e+11 | I21: 3.5891902e+12 | J21: 4.0777696e+12 | M21: 4.0777696e+12 | N21: 0 | O21: 1.0904926e+11 | P21: 1.3783408e+12 | Q21: 5.5651597e+12
A22: 122 | B22: 140401 | C22: 1.0248113e+12 | D22: 3.1856237e+11 | E22: 9.7561979e+12 | F22: 1.1099572e+13 | G22: 1.1703561e+12 | H22: 3.6380491e+11 | I22: 9.5073173e+12 | J22: 1.1041478e+13 | M22: 1.1041478e+13 | N22: 0 | O22: 2.5075835e+10 | P22: 1.8163234e+10 | Q22: 1.1084717e+13
A23: 123 | B23: 140401 | C23: 8.9758244e+11 | D23: 6.1906176e+11 | E23: 24115490419476 | F23: 2.5632135e+13 | G23: 1.025058e+12 | H23: 7.0698153e+11 | I23: 21623660909922 | J23: 2.33557e+13 | K23: 1 | L23: 0.414167 | M23: 17853478108693 | N23: 0 | O23: 4.8644853e+11 | P23: 1.108092e+13 | Q23: 2.9420847e+13
A24: 124 | B24: 140401 | C24: 4.8530758e+11 | D24: 5.9716998e+12 | E24: 9.1036428e+12 | F24: 1.556065e+13 | G24: 5.5423144e+11 | H24: 6.8198065e+12 | I24: 8.1712659e+12 | J24: 1.5545304e+13 | K24: 2 | L24: 0.617385 | M24: 7.7592519e+12 | N24: 0 | O24: 3.6108556e+10 | P24: 7.9295557e+11 | Q24: 8.588316e+12
A25: 125 | B25: 140401 | C25: 4.2513821e+11 | D25: 2.5689936e+11 | E25: 8.4058195e+12 | F25: 9.0878571e+12 | G25: 4.8551676e+11 | H25: 2.9338446e+11 | I25: 7.9206356e+12 | J25: 8.6995369e+12 | M25: 8.6995369e+12 | N25: 1.2205675e+10 | O25: 7934330047 | P25: 5.8756376e+10 | Q25: 8.7784332e+12
A26: 126 | B26: 140401 | C26: 3.4266042e+11 | D26: 2.0846626e+11 | E26: 1.3918613e+13 | F26: 1.4469739e+13 | G26: 3.913254e+11 | H26: 2.3807285e+11 | I26: 1.3081352e+13 | J26: 1.3710751e+13 | M26: 1.3710751e+13 | N26: 0 | O26: 3.5966074e+10 | P26: 1.632833e+12 | Q26: 1.537955e+13
A27: 127 | B27: 140401 | C27: 1.375086e+12 | D27: 2.7255198e+11 | E27: 7.5763696e+12 | F27: 9.2240076e+12 | G27: 1.5703771e+12 | H27: 3.1126008e+11 | I27: 7.3033779e+12 | J27: 9.1850151e+12 | M27: 9.1850151e+12 | N27: 18332520425 | O27: 2.6662132e+11 | P27: 4.9032137e+12 | Q27: 1.4373183e+13
A28: 128 | B28: 140401 | C28: 9.9870394e+10 | D28: 1.7267839e+11 | E28: 6915668990042 | F28: 7.1882178e+12 | G28: 1.1405409e+11 | H28: 1.9720235e+11 | I28: 6.6165732e+12 | J28: 6.9278297e+12 | M28: 6.9278297e+12 | N28: 0 | O28: 955000000 | P28: 3.1939511e+10 | Q28: 6.9607242e+12
A29: 129 | B29: 140401 | C29: 3.3526272e+11 | D29: 2.3925414e+11 | E29: 8.0423442e+12 | F29: 8.616861e+12 | G29: 3.8287707e+11 | H29: 2.7323326e+11 | I29: 7.7640951e+12 | J29: 8.4202055e+12 | M29: 8.4202055e+12 | N29: 0 | O29: 4.9965748e+10 | P29: 4.991118e+11 | Q29: 8.969283e+12
A30: 130 | B30: 140401 | C30: 9.0399322e+11 | D30: 8.3373177e+11 | E30: 6.5811755e+12 | F30: 8.3189005e+12 | G30: 1.0323792e+12 | H30: 9.5213919e+11 | I30: 6.3710254e+12 | J30: 8.3555438e+12 | K30: 1 | L30: 0.251921 | M30: 7.8783328e+12 | N30: 2.9632994e+10 | O30: 2.0148609e+11 | P30: 2.5605812e+12 | Q30: 1.0670033e+13
A31: 132 | B31: 140401 | C31: 173403367898 | D31: 2.3180894e+11 | E31: 7.2817362e+12 | F31: 7.6869485e+12 | G31: 1.9803029e+11 | H31: 2.6473068e+11 | I31: 6.9255283e+12 | J31: 7.3882892e+12 | M31: 7.3882892e+12 | N31: 0 | O31: 3.4319509e+09 | P31: 5.0576935e+09 | Q31: 7.3967789e+12
A32: 133 | B32: 140401 | C32: 8.6174342e+11 | D32: 3.043357e+11 | E32: 17697430219990 | F32: 1.8863509e+13 | G32: 9.8412908e+11 | H32: 3.4755777e+11 | I32: 1.4994325e+13 | J32: 1.6326012e+13 | K32: 1 | L32: 0.544579 | M32: 1.0137851e+13 | N32: 0 | O32: 1.8522043e+11 | P32: 3.8955628e+11 | Q32: 1.0712627e+13
A33: 134 | B33: 140401 | C33: 690888529726 | D33: 1.5925667e+11 | E33: 7.8549424e+12 | F33: 8.7050876e+12 | G33: 7.8900921e+11 | H33: 1.8187446e+11 | I33: 7.2312128e+12 | J33: 8.2020965e+12 | M33: 8.2020965e+12 | N33: 0 | O33: 2.0164697e+11 | P33: 2.411244e+12 | Q33: 1.0814987e+13
A34: 135 | B34: 140401 | C34: 2.4821981e+11 | D34: 2.9501554e+11 | E34: 1.0685195e+13 | F34: 11228430834386 | G34: 2.8347224e+11 | H34: 3.3691394e+11 | I34: 9.909835e+12 | J34: 1.0530221e+13 | M34: 1.0530221e+13 | N34: 0 | O34: 1.9127147e+11 | P34: 8.4679858e+11 | Q34: 11568291185217
A35: 136 | B35: 140401 | C35: 4.2268185e+11 | D35: 1.4536583e+11 | E35: 8.5436218e+12 | F35: 9.1116695e+12 | G35: 4.8271155e+11 | H35: 1.6601083e+11 | I35: 8.3337306e+12 | J35: 8.982453e+12 | M35: 8.982453e+12 | N35: 1.3781647e+09 | O35: 4.0164364e+11 | P35: 3.8774695e+11 | Q35: 9.7732217e+12
A36: 140 | B36: 140401 | C36: 3.3306227e+11 | D36: 1.8859869e+11 | E36: 7.6171766e+12 | F36: 8.1388376e+12 | G36: 3.803641e+11 | H36: 2.1538367e+11 | I36: 7.0877143e+12 | J36: 7.683462e+12 | M36: 7.683462e+12 | N36: 0 | O36: 2.5637767e+10 | P36: 6.0960988e+09 | Q36: 7.7151959e+12
A37: 141 | B37: 140401 | C37: 4.8462449e+11 | D37: 3.609953e+11 | E37: 8.9222307e+12 | F37: 9.7678505e+12 | G37: 5.5345134e+11 | H37: 4.1226422e+11 | I37: 8.6249509e+12 | J37: 9.5906665e+12 | M37: 9.5906665e+12 | N37: 0 | O37: 7.6328279e+09 | P37: 6.0725562e+09 | Q37: 9.6043719e+12
A38: 142 | B38: 140401 | C38: 2.0209508e+12 | D38: 2815644937767 | E38: 1.4266542e+13 | F38: 1.9103138e+13 | G38: 2.3079683e+12 | H38: 3.2155256e+12 | I38: 1.388253e+13 | J38: 1.9406024e+13 | M38: 1.9406024e+13 | N38: 4.0710615e+10 | O38: 2.1289215e+12 | P38: 1.2065081e+13 | Q38: 3.3640737e+13
A39: 143 | B39: 140401 | C39: 5.5070231e+11 | D39: 2.4605077e+11 | E39: 8.2439649e+12 | F39: 9.040718e+12 | G39: 6.289136e+11 | H39: 2.8099515e+11 | I39: 7.9519389e+12 | J39: 8.8618477e+12 | M39: 8.8618477e+12 | N39: 13197969129 | O39: 104318526433 | P39: 4.9766269e+11 | Q39: 9.4770268e+12
A40: 145 | B40: 140401 | C40: 113236818832 | D40: 1.1011101e+11 | E40: 2.3536803e+12 | F40: 2.5770281e+12 | G40: 1.2931883e+11 | H40: 1.2574909e+11 | I40: 2.3066914e+12 | J40: 2.5617593e+12 | M40: 2.5617593e+12 | N40: 0 | O40: 1.5107516e+09 | P40: 1.7532077e+11 | Q40: 2.7385908e+12
...

Sheet تعداد سپرده ها
A1: branchcode | B1: SHYEARMONTH | C1: miangin_tedad_sepordeha
A2: 101 | B2: 140401 | C2: 33324
A3: 101 | B3: 140402 | C3: 33384
A4: 101 | B4: 140403 | C4: 33446
A5: 101 | B5: 140404 | C5: 34334
A6: 101 | B6: 140405 | C6: 33563
A7: 101 | B7: 140406 | C7: 33618
A8: 101 | B8: 140407 | C8: 33680
A9: 101 | B9: 140408 | C9: 33750
A10: 101 | B10: 140409 | C10: 33821
A11: 101 | B11: 140410 | C11: 33894
A12: 101 | B12: 140411 | C12: 33963
A13: 101 | B13: 140412 | C13: 34024
... A2677: 4021 | B2677: 140412 | C2677: 39663

Sheet میانگین مانده تسهیلات
A1: ID_Branch | B1: SHYEARMONTH | C1: miangin_mande_tashilat
A2: 101 | B2: 140401 | C2: 71746145824109
A3: 101 | B3: 140402 | C3: 72354803018084
A4: 101 | B4: 140403 | C4: 75310168200362
A5: 101 | B5: 140404 | C5: 77203154104240
A6: 101 | B6: 140405 | C6: 79092575618694
A7: 101 | B7: 140406 | C7: 81775023290367
A8: 101 | B8: 140407 | C8: 84809294385553
A9: 101 | B9: 140408 | C9: 87896298616221
A10: 101 | B10: 140409 | C10: 90544133977166
A11: 101 | B11: 140410 | C11: 93768469205084
A12: 101 | B12: 140411 | C12: 97247631534211
A13: 101 | B13: 140412 | C13: 100553010621487
... A2677: 4021 | B2677: 140412 | C2677: 477323535305

Sheet میانگین تعهدات
A1: ID_Branch | B1: SHYEARMONTH | C1: Avg_Taahodat
A2: 101 | B2: 140401 | C2: 86585015150571
A3: 101 | B3: 140402 | C3: 86993354543585
A4: 101 | B4: 140403 | C4: 88968296405140
A5: 101 | B5: 140404 | C5: 89779973119159
A6: 101 | B6: 140405 | C6: 90497502894305
A7: 101 | B7: 140406 | C7: 91264853503753
A8: 101 | B8: 140407 | C8: 91609117034739
A9: 101 | B9: 140408 | C9: 91993948906295
A10: 101 | B10: 140409 | C10: 92634475350035
A11: 101 | B11: 140410 | C11: 93460999705519
A12: 101 | B12: 140411 | C12: 94362688172843
A13: 101 | B13: 140412 | C13: 94791944348430
... A1489: 1502 | B1489: 140412 | C1489: 203279209706
A1490: 1521 | B1490: 140401
A1491: 1521 | B1491: 140402 | C1491: 532258065
A1492: 1521 | B1492: 140403 | C1492: 2286401745
A1493: 1521 | B1493: 140404 | C1493: 2326898082
A1494: 1521 | B1494: 140405 | C1494: 2723755529
A1495: 1521 | B1495: 140406 | C1495: 2292645736
A1496: 1521 | B1496: 140407 | C1496: 3393048193
A1497: 1521 | B1497: 140408 | C1497: 4481706209
A1498: 1521 | B1498: 140409 | C1498: 5453459574
A1499: 1521 | B1499: 140410 | C1499: 5644691279
A1500: 1521 | B1500: 140411 | C1500: 7286736797
A1501: 1521 | B1501: 140412 | C1501: 15044751439
A1502: 1531 | B1502: 140401 | C1502: 16997969328
... A2677: 4021 | B2677: 140412 | C2677: 649329291858

Sheet تعداد حجم عملیات
A1: ID_Branch | B1: SHYEARMONTH | C1: count_hajme_amaliat
A2: 101 | B2: 140401 | C2: 10736
A3: 101 | B3: 140402 | C3: 26872
A4: 101 | B4: 140403 | C4: 38603
A5: 101 | B5: 140404 | C5: 55764
A6: 101 | B6: 140405 | C6: 70316
A7: 101 | B7: 140406 | C7: 86773
A8: 101 | B8: 140407 | C8: 103042
A9: 101 | B9: 140408 | C9: 119206
A10: 101 | B10: 140409 | C10: 134724
A11: 101 | B11: 140410 | C11: 150764
A12: 101 | B12: 140411 | C12: 166889
A13: 101 | B13: 140412 | C13: 181485
... A217: 119 | B217: 140412 | C217: 165083
A218: 120 | B218: 140401 | C218: NULL
A219: 120 | B219: 140402 | C219: NULL
A220: 120 | B220: 140403 | C220: NULL
A221: 120 | B221: 140404 | C221: NULL
A222: 120 | B222: 140405 | C222: NULL
A223: 120 | B223: 140406 | C223: NULL
A224: 120 | B224: 140407 | C224: NULL
A225: 120 | B225: 140408 | C225: 3956
A226: 120 | B226: 140409 | C226: 6435
A227: 120 | B227: 140410 | C227: 9152
A228: 120 | B228: 140411 | C228: 12297
A229: 120 | B229: 140412 | C229: 15799
A230: 121 | B230: 140401 | C230: 10517
A231: 121 | B231: 140402 | C231: 26077
A232: 121 | B232: 140403 | C232: 38421
A233: 121 | B233: 140404 | C233: 52587
A234: 121 | B234: 140405 | C234: 67352
A235: 121 | B235: 140406 | C235: 83401
A236: 121 | B236: 140407 | C236: 99537
... A2677: 4021 | B2677: 140412 | C2677: 57622

Sheet میانگین تعداد تسهیلات
A1: ID_Branch | B1: SHYEARMONTH | C1: miangin_tedad_tashilat
A2: 101 | B2: 140401 | C2: 568
A3: 101 | B3: 140402 | C3: 571
A4: 101 | B4: 140403 | C4: 580
A5: 101 | B5: 140404 | C5: 585
A6: 101 | B6: 140405 | C6: 591
A7: 101 | B7: 140406 | C7: 599
A8: 101 | B8: 140407 | C8: 607
A9: 101 | B9: 140408 | C9: 617
A10: 101 | B10: 140409 | C10: 626
A11: 101 | B11: 140410 | C11: 641
A12: 101 | B12: 140411 | C12: 658
A13: 101 | B13: 140412 | C13: 674
... A2677: 4021 | B2677: 140412 | C2677: 138

Sheet میانگین تعداد تعهدات
A1: ID_Branch | B1: SHYEARMONTH | C1: Avg_Taahodat
A2: 101 | B2: 140401 | C2: 395
A3: 101 | B3: 140402 | C3: 397
A4: 101 | B4: 140403 | C4: 398
A5: 101 | B5: 140404 | C5: 398
A6: 101 | B6: 140405 | C6: 398
A7: 101 | B7: 140406 | C7: 398
A8: 101 | B8: 140407 | C8: 400
A9: 101 | B9: 140408 | C9: 402
A10: 101 | B10: 140409 | C10: 404
A11: 101 | B11: 140410 | C11: 406
A12: 101 | B12: 140411 | C12: 408
A13: 101 | B13: 140412 | C13: 408
... A1489: 1502 | B1489: 140412 | C1489: 20
A1490: 1521 | B1490: 140401
A1491: 1521 | B1491: 140402
A1492: 1521 | B1492: 140403
A1493: 1521 | B1493: 140404
A1494: 1521 | B1494: 140405
A1495: 1521 | B1495: 140406
A1496: 1521 | B1496: 140407
A1497: 1521 | B1497: 140408
A1498: 1521 | B1498: 140409
A1499: 1521 | B1499: 140410 | C1499: 1
A1500: 1521 | B1500: 140411 | C1500: 1
A1501: 1521 | B1501: 140412 | C1501: 1
A1502: 1531 | B1502: 140401 | C1502: 4
A1503: 1531 | B1503: 140402 | C1503: 3
A1504: 1531 | B1504: 140403 | C1504: 3
A1505: 1531 | B1505: 140404 | C1505: 3
A1506: 1531 | B1506: 140405 | C1506: 3
A1507: 1531 | B1507: 140406 | C1507: 3
A1508: 1531 | B1508: 140407 | C1508: 3
A1509: 1531 | B1509: 140408 | C1509: 3
A1510: 1531 | B1510: 140409 | C1510: 4
... A2677: 4021 | B2677: 140412 | C2677: 21

Sheet سود و زیان
A1: SHYEARMONTH | B1: branchcode | C1: mande_SoodoZian
A2: 140401 | B2: 101 | C2: 847176153291
A3: 140402 | B3: 101 | C3: 1369291872461
A4: 140403 | B4: 101 | C4: 1864990033727
A5: 140404 | B5: 101 | C5: 2872041379756
A6: 140405 | B6: 101 | C6: 3557778482851
A7: 140406 | B7: 101 | C7: 4261063861674
A8: 140407 | B8: 101 | C8: 5119478162800
A9: 140408 | B9: 101 | C9: 5870129622504
A10: 140409 | B10: 101 | C10: 6902075918097
A11: 140410 | B11: 101 | C11: 7902460351320
A12: 140411 | B12: 101 | C12: 9879073572427
A13: 140412 | B13: 101 | C13: 10765429399129
... A2677: 140412 | B2677: 4021 | C2677: 226579527465

Sheet ميانگين نرخ سود كل سپرده ها
A1: SHYEARMONTH | B1: AvgRate
A2: 140401 | B2: 14.202105
A3: 140402 | B3: 14.763083
A4: 140403 | B4: 14.926637
A5: 140404 | B5: 14.953677
A6: 140405 | B6: 14.963493
A7: 140406 | B7: 14.944305
A8: 140407 | B8: 14.918911
A9: 140408 | B9: 14.882035
A10: 140409 | B10: 14.841207
A11: 140410 | B11: 14.800881
A12: 140411 | B12: 14.763271
A13: 140412 | B13: 14.728126

Sheet ميانگين نرخ سود سپرده هاي مدت د
A1: ID_Branch | B1: SHYEARMONTH | C1: DepositRate
A2: 101 | B2: 140401 | C2: 10.445118
A3: 101 | B3: 140402 | C3: 10.361012
A4: 101 | B4: 140403 | C4: 10.280496
A5: 101 | B5: 140404 | C5: 10.093251
A6: 101 | B6: 140405 | C6: 9.968383
A7: 101 | B7: 140406 | C7: 10.078421
A8: 101 | B8: 140407 | C8: 10.241105
A9: 101 | B9: 140408 | C9: 10.461136
A10: 101 | B10: 140409 | C10: 10.686499
A11: 101 | B11: 140410 | C11: 10.861306
A12: 101 | B12: 140411 | C12: 10.988992
A13: 101 | B13: 140412 | C13: 11.06917
... A2677: 4021 | B2677: 140412 | C2677: 15.936674
